<?xml version="1.0"?>
<robot xmlns:xacro="http://www.ros.org/wiki/xacro" name="mobile_robot">
    <xacro:include filename="$(find mobilerobot)/urdf/model_robot.gazebo.xacro"/>
    <xacro:property name="length" value="0.05"/>
    <xacro:property name="radius" value="0.05"/>
    <material name="rubber">
        <color rgba="0 0 0 1"/>
    </material>
    <material name="hard_plastic">
        <color rgba="0.3098 0.3098 0.3098 1.0"/>
    </material>

    <xacro:macro name="wheel" params="name location_x location_y location_z">
        <link name="${name}">
            <visual>
                <geometry>
                    <cylinder length="${length}" radius="${radius}"/>
                </geometry>
                <origin xyz="0 0 0" rpy="1.5707 0 0"/>
                <material name="rubber"/>
            </visual>
            <collision>
                <geometry>
                    <cylinder length="${length}" radius="${radius}"/>
                </geometry>
                <origin xyz="0 0 0" rpy="1.5707 0 0"/>
            </collision>
            <inertial>
                <mass value="1"/>
                <inertia ixx="0.0008" iyy="0.0008" izz="0.00125" ixy="0" ixz="0" iyz="0"/>
            </inertial>
        </link>
        <joint name="${name}_to_base_link" type="continuous">
            <axis xyz="0 1 0" rpy="0 0 0"/>
            <parent link="base_link"/>
            <child link="${name}"/>
            <origin xyz="${location_x} ${location_y} ${location_z}" rpy="0 0 0"/>
        </joint>
    </xacro:macro>

    <xacro:macro name="base_link" params="location_x location_y location_z">
        <link name="base_link">
            <origin xyz="${location_x} ${location_y} ${location_z}" rpy="0.0 0.0 0.0"/>    
            <visual>
                <geometry>
                    <box size="0.2 0.2 0.025"/>
                </geometry>
                <material name="hard_plastic"/>
            </visual>
            <collision>
                <geometry>
                    <box size="0.2 0.2 0.09"/>
                </geometry>
            </collision>
            <inertial>
                <mass value="3"/>
                <inertia ixx="0.010625" iyy="0.010625" izz="0.02" ixy="0" ixz="0" iyz="0"/>
            </inertial>
        </link>
    </xacro:macro>

    <xacro:base_link location_x="0" location_y="0" location_z="0"/>
    <xacro:wheel name="wheel_right" location_x="0" location_y="-0.125" location_z="0"/>
    <xacro:wheel name="wheel_left" location_x="0" location_y="0.125" location_z="0"/>   

</robot>
